INFO 2019-08-30 15:06:57,076 /home/liu/.virtualenvs/python2/local/lib/python2.7/site-packages/django/core/servers/basehttp.py basehttp.py basehttp log_message 124: "GET / HTTP/1.1" 200 5799
INFO 2019-08-30 15:06:57,125 /home/liu/.virtualenvs/python2/local/lib/python2.7/site-packages/django/core/servers/basehttp.py basehttp.py basehttp log_message 124: "GET /static/ui/h-ui.admin/css/H-ui.admin.css HTTP/1.1" 200 7185
INFO 2019-08-30 15:06:57,131 /home/liu/.virtualenvs/python2/local/lib/python2.7/site-packages/django/core/servers/basehttp.py basehttp.py basehttp log_message 124: "GET /static/ui/h-ui/css/H-ui.min.css HTTP/1.1" 200 152330
INFO 2019-08-30 15:06:57,133 /home/liu/.virtualenvs/python2/local/lib/python2.7/site-packages/django/core/servers/basehttp.py basehttp.py basehttp log_message 124: "GET /static/ui/h-ui.admin/skin/blue/skin.css HTTP/1.1" 200 1280
INFO 2019-08-30 15:06:57,137 /home/liu/.virtualenvs/python2/local/lib/python2.7/site-packages/django/core/servers/basehttp.py basehttp.py basehttp log_message 124: "GET /static/lib/Hui-iconfont/1.0.8/iconfont.css HTTP/1.1" 200 16919
INFO 2019-08-30 15:06:57,140 /home/liu/.virtualenvs/python2/local/lib/python2.7/site-packages/django/core/servers/basehttp.py basehttp.py basehttp log_message 124: "GET /static/ui/h-ui.admin/css/style.css HTTP/1.1" 200 1059
INFO 2019-08-30 15:06:57,142 /home/liu/.virtualenvs/python2/local/lib/python2.7/site-packages/django/core/servers/basehttp.py basehttp.py basehttp log_message 124: "GET /static/lib/jquery/1.9.1/jquery.min.js HTTP/1.1" 200 92629
INFO 2019-08-30 15:06:57,142 /home/liu/.virtualenvs/python2/local/lib/python2.7/site-packages/django/core/servers/basehttp.py basehttp.py basehttp log_message 124: "GET /static/lib/layer/2.4/layer.js HTTP/1.1" 200 19843
INFO 2019-08-30 15:06:57,151 /home/liu/.virtualenvs/python2/local/lib/python2.7/site-packages/django/core/servers/basehttp.py basehttp.py basehttp log_message 124: "GET /static/ui/h-ui/js/H-ui.min.js HTTP/1.1" 200 149504
INFO 2019-08-30 15:06:57,155 /home/liu/.virtualenvs/python2/local/lib/python2.7/site-packages/django/core/servers/basehttp.py basehttp.py basehttp log_message 124: "GET /static/ui/h-ui.admin/js/H-ui.admin.js HTTP/1.1" 200 9008
INFO 2019-08-30 15:06:57,156 /home/liu/.virtualenvs/python2/local/lib/python2.7/site-packages/django/core/servers/basehttp.py basehttp.py basehttp log_message 124: "GET /static/lib/spin/spin.js HTTP/1.1" 200 0
INFO 2019-08-30 15:06:57,161 /home/liu/.virtualenvs/python2/local/lib/python2.7/site-packages/django/core/servers/basehttp.py basehttp.py basehttp log_message 124: "GET /static/ui/js/netapp.js HTTP/1.1" 200 4587
INFO 2019-08-30 15:06:57,162 /home/liu/.virtualenvs/python2/local/lib/python2.7/site-packages/django/core/servers/basehttp.py basehttp.py basehttp log_message 124: "GET /static/ui/js/index.js HTTP/1.1" 200 7259
INFO 2019-08-30 15:06:57,186 /home/liu/.virtualenvs/python2/local/lib/python2.7/site-packages/django/core/servers/basehttp.py basehttp.py basehttp log_message 124: "GET /welcome HTTP/1.1" 301 0
INFO 2019-08-30 15:06:57,190 /home/liu/.virtualenvs/python2/local/lib/python2.7/site-packages/django/core/servers/basehttp.py basehttp.py basehttp log_message 124: "GET /welcome/ HTTP/1.1" 200 2359
INFO 2019-08-30 15:06:57,223 /home/liu/.virtualenvs/python2/local/lib/python2.7/site-packages/django/core/servers/basehttp.py basehttp.py basehttp log_message 124: "GET /static/ui/h-ui.admin/skin/blue/icon_arrow.png HTTP/1.1" 200 3287
INFO 2019-08-30 15:06:57,226 /home/liu/.virtualenvs/python2/local/lib/python2.7/site-packages/django/core/servers/basehttp.py basehttp.py basehttp log_message 124: "GET /static/ui/h-ui.admin/images/acrossTab/acrossTab-2.png HTTP/1.1" 200 5710
INFO 2019-08-30 15:06:57,226 /home/liu/.virtualenvs/python2/local/lib/python2.7/site-packages/django/core/servers/basehttp.py basehttp.py basehttp log_message 124: "GET /static/ui/h-ui.admin/images/loading.gif HTTP/1.1" 200 8476
INFO 2019-08-30 15:06:57,293 /home/liu/.virtualenvs/python2/local/lib/python2.7/site-packages/django/core/servers/basehttp.py basehttp.py basehttp log_message 124: "GET /static/lib/Hui-iconfont/1.0.8/iconfont.woff HTTP/1.1" 200 80688
INFO 2019-08-30 15:06:57,329 /home/liu/.virtualenvs/python2/local/lib/python2.7/site-packages/django/core/servers/basehttp.py basehttp.py basehttp log_message 124: "GET /static/ui/h-ui.admin/skin/default/skin.css HTTP/1.1" 200 1193
INFO 2019-08-30 15:06:57,330 /home/liu/.virtualenvs/python2/local/lib/python2.7/site-packages/django/core/servers/basehttp.py basehttp.py basehttp log_message 124: "GET /static/ui//h-ui.admin/css/H-ui.admin.css HTTP/1.1" 200 7185
INFO 2019-08-30 15:06:57,339 /home/liu/.virtualenvs/python2/local/lib/python2.7/site-packages/django/core/servers/basehttp.py basehttp.py basehttp log_message 124: "GET /static/lib/My97DatePicker/4.8/WdatePicker.js HTTP/1.1" 200 10235
INFO 2019-08-30 15:06:57,340 /home/liu/.virtualenvs/python2/local/lib/python2.7/site-packages/django/core/servers/basehttp.py basehttp.py basehttp log_message 124: "GET /static/lib/laypage/1.2/laypage.js HTTP/1.1" 200 3673
INFO 2019-08-30 15:06:57,349 /home/liu/.virtualenvs/python2/local/lib/python2.7/site-packages/django/core/servers/basehttp.py basehttp.py basehttp log_message 124: "GET /static/lib/layer/2.4/skin/layer.css HTTP/1.1" 200 14048
INFO 2019-08-30 15:06:57,350 /home/liu/.virtualenvs/python2/local/lib/python2.7/site-packages/django/core/servers/basehttp.py basehttp.py basehttp log_message 124: "GET /static/lib/datatables/1.10.0/jquery.dataTables.min.js HTTP/1.1" 200 75893
ERROR 2019-08-30 15:06:57,535 /home/liu/.virtualenvs/python2/local/lib/python2.7/site-packages/django/core/handlers/exception.py exception.py exception handle_uncaught_exception 135: Internal Server Error: /initindexbar/
Traceback (most recent call last):
  File "/home/liu/.virtualenvs/python2/local/lib/python2.7/site-packages/django/core/handlers/exception.py", line 41, in inner
    response = get_response(request)
  File "/home/liu/.virtualenvs/python2/local/lib/python2.7/site-packages/django/core/handlers/base.py", line 249, in _legacy_get_response
    response = self._get_response(request)
  File "/home/liu/.virtualenvs/python2/local/lib/python2.7/site-packages/django/core/handlers/base.py", line 187, in _get_response
    response = self.process_exception_by_middleware(e, request)
  File "/home/liu/.virtualenvs/python2/local/lib/python2.7/site-packages/django/core/handlers/base.py", line 185, in _get_response
    response = wrapped_callback(request, *callback_args, **callback_kwargs)
  File "/home/liu/.virtualenvs/python2/local/lib/python2.7/site-packages/django/views/decorators/csrf.py", line 58, in wrapped_view
    return view_func(*args, **kwargs)
  File "/home/liu/PycharmProjects/USMP/index/views.py", line 50, in initIndexBar
    for cluster in nas_cluster_result:
  File "/home/liu/.virtualenvs/python2/local/lib/python2.7/site-packages/django/db/models/query.py", line 250, in __iter__
    self._fetch_all()
  File "/home/liu/.virtualenvs/python2/local/lib/python2.7/site-packages/django/db/models/query.py", line 1121, in _fetch_all
    self._result_cache = list(self._iterable_class(self))
  File "/home/liu/.virtualenvs/python2/local/lib/python2.7/site-packages/django/db/models/query.py", line 106, in __iter__
    for row in compiler.results_iter(chunked_fetch=self.chunked_fetch):
  File "/home/liu/.virtualenvs/python2/local/lib/python2.7/site-packages/django/db/models/sql/compiler.py", line 841, in results_iter
    results = self.execute_sql(MULTI, chunked_fetch=chunked_fetch)
  File "/home/liu/.virtualenvs/python2/local/lib/python2.7/site-packages/django/db/models/sql/compiler.py", line 899, in execute_sql
    raise original_exception
ProgrammingError: (1146, u"Table 'usmpdb.nas_cluster' doesn't exist")
INFO 2019-08-30 15:06:57,543 /home/liu/.virtualenvs/python2/local/lib/python2.7/site-packages/django/core/servers/basehttp.py basehttp.py basehttp log_message 124: "GET /static/lib/My97DatePicker/4.8/skin/WdatePicker.css HTTP/1.1" 200 144
ERROR 2019-08-30 15:06:57,637 /home/liu/.virtualenvs/python2/local/lib/python2.7/site-packages/django/core/servers/basehttp.py basehttp.py basehttp log_message 124: "POST /initindexbar/ HTTP/1.1" 500 18908
INFO 2019-08-30 15:06:57,638 /home/liu/.virtualenvs/python2/local/lib/python2.7/site-packages/django/core/servers/basehttp.py basehttp.py basehttp log_message 124: "GET /static/image/favicon.ico HTTP/1.1" 200 4286
INFO 2019-08-30 15:07:00,654 /home/liu/.virtualenvs/python2/local/lib/python2.7/site-packages/django/core/servers/basehttp.py basehttp.py basehttp log_message 124: "GET /welcome/ HTTP/1.1" 200 2359
WARNING 2019-08-30 15:16:28,339 /home/liu/.virtualenvs/python2/local/lib/python2.7/site-packages/django/core/handlers/base.py base.py base get_response 182: Not Found: /wlecome
WARNING 2019-08-30 15:16:28,389 /home/liu/.virtualenvs/python2/local/lib/python2.7/site-packages/django/core/handlers/base.py base.py base get_response 182: Not Found: /favicon.ico
ERROR 2019-08-30 15:17:44,563 /home/liu/.virtualenvs/python2/local/lib/python2.7/site-packages/django/core/handlers/base.py base.py base handle_uncaught_exception 284: Internal Server Error: /initindexbar/
Traceback (most recent call last):
  File "/home/liu/.virtualenvs/python2/local/lib/python2.7/site-packages/django/core/handlers/base.py", line 149, in get_response
    response = self.process_exception_by_middleware(e, request)
  File "/home/liu/.virtualenvs/python2/local/lib/python2.7/site-packages/django/core/handlers/base.py", line 147, in get_response
    response = wrapped_callback(request, *callback_args, **callback_kwargs)
  File "/home/liu/.virtualenvs/python2/local/lib/python2.7/site-packages/django/views/decorators/csrf.py", line 58, in wrapped_view
    return view_func(*args, **kwargs)
  File "/home/liu/PycharmProjects/USMP/index/views.py", line 50, in initIndexBar
    for cluster in nas_cluster_result:
  File "/home/liu/.virtualenvs/python2/local/lib/python2.7/site-packages/django/db/models/query.py", line 258, in __iter__
    self._fetch_all()
  File "/home/liu/.virtualenvs/python2/local/lib/python2.7/site-packages/django/db/models/query.py", line 1074, in _fetch_all
    self._result_cache = list(self.iterator())
  File "/home/liu/.virtualenvs/python2/local/lib/python2.7/site-packages/django/db/models/query.py", line 112, in __iter__
    for row in compiler.results_iter():
  File "/home/liu/.virtualenvs/python2/local/lib/python2.7/site-packages/django/db/models/sql/compiler.py", line 802, in results_iter
    results = self.execute_sql(MULTI)
  File "/home/liu/.virtualenvs/python2/local/lib/python2.7/site-packages/django/db/models/sql/compiler.py", line 848, in execute_sql
    cursor.execute(sql, params)
  File "/home/liu/.virtualenvs/python2/local/lib/python2.7/site-packages/django/db/backends/utils.py", line 79, in execute
    return super(CursorDebugWrapper, self).execute(sql, params)
  File "/home/liu/.virtualenvs/python2/local/lib/python2.7/site-packages/django/db/backends/utils.py", line 64, in execute
    return self.cursor.execute(sql, params)
  File "/home/liu/.virtualenvs/python2/local/lib/python2.7/site-packages/django/db/utils.py", line 95, in __exit__
    six.reraise(dj_exc_type, dj_exc_value, traceback)
  File "/home/liu/.virtualenvs/python2/local/lib/python2.7/site-packages/django/db/backends/utils.py", line 64, in execute
    return self.cursor.execute(sql, params)
  File "/home/liu/.virtualenvs/python2/local/lib/python2.7/site-packages/django/db/backends/mysql/base.py", line 112, in execute
    return self.cursor.execute(query, args)
  File "/home/liu/.virtualenvs/python2/local/lib/python2.7/site-packages/pymysql/cursors.py", line 170, in execute
    result = self._query(query)
  File "/home/liu/.virtualenvs/python2/local/lib/python2.7/site-packages/pymysql/cursors.py", line 328, in _query
    conn.query(q)
  File "/home/liu/.virtualenvs/python2/local/lib/python2.7/site-packages/pymysql/connections.py", line 517, in query
    self._affected_rows = self._read_query_result(unbuffered=unbuffered)
  File "/home/liu/.virtualenvs/python2/local/lib/python2.7/site-packages/pymysql/connections.py", line 732, in _read_query_result
    result.read()
  File "/home/liu/.virtualenvs/python2/local/lib/python2.7/site-packages/pymysql/connections.py", line 1075, in read
    first_packet = self.connection._read_packet()
  File "/home/liu/.virtualenvs/python2/local/lib/python2.7/site-packages/pymysql/connections.py", line 684, in _read_packet
    packet.check_error()
  File "/home/liu/.virtualenvs/python2/local/lib/python2.7/site-packages/pymysql/protocol.py", line 220, in check_error
    err.raise_mysql_exception(self._data)
  File "/home/liu/.virtualenvs/python2/local/lib/python2.7/site-packages/pymysql/err.py", line 109, in raise_mysql_exception
    raise errorclass(errno, errval)
ProgrammingError: (1146, u"Table 'usmpdb.nas_cluster' doesn't exist")
ERROR 2019-08-30 15:18:00,665 /home/liu/.virtualenvs/python2/local/lib/python2.7/site-packages/django/core/handlers/base.py base.py base handle_uncaught_exception 284: Internal Server Error: /initindexbar/
Traceback (most recent call last):
  File "/home/liu/.virtualenvs/python2/local/lib/python2.7/site-packages/django/core/handlers/base.py", line 149, in get_response
    response = self.process_exception_by_middleware(e, request)
  File "/home/liu/.virtualenvs/python2/local/lib/python2.7/site-packages/django/core/handlers/base.py", line 147, in get_response
    response = wrapped_callback(request, *callback_args, **callback_kwargs)
  File "/home/liu/.virtualenvs/python2/local/lib/python2.7/site-packages/django/views/decorators/csrf.py", line 58, in wrapped_view
    return view_func(*args, **kwargs)
  File "/home/liu/PycharmProjects/USMP/index/views.py", line 50, in initIndexBar
    for cluster in nas_cluster_result:
  File "/home/liu/.virtualenvs/python2/local/lib/python2.7/site-packages/django/db/models/query.py", line 258, in __iter__
    self._fetch_all()
  File "/home/liu/.virtualenvs/python2/local/lib/python2.7/site-packages/django/db/models/query.py", line 1074, in _fetch_all
    self._result_cache = list(self.iterator())
  File "/home/liu/.virtualenvs/python2/local/lib/python2.7/site-packages/django/db/models/query.py", line 112, in __iter__
    for row in compiler.results_iter():
  File "/home/liu/.virtualenvs/python2/local/lib/python2.7/site-packages/django/db/models/sql/compiler.py", line 802, in results_iter
    results = self.execute_sql(MULTI)
  File "/home/liu/.virtualenvs/python2/local/lib/python2.7/site-packages/django/db/models/sql/compiler.py", line 848, in execute_sql
    cursor.execute(sql, params)
  File "/home/liu/.virtualenvs/python2/local/lib/python2.7/site-packages/django/db/backends/utils.py", line 79, in execute
    return super(CursorDebugWrapper, self).execute(sql, params)
  File "/home/liu/.virtualenvs/python2/local/lib/python2.7/site-packages/django/db/backends/utils.py", line 64, in execute
    return self.cursor.execute(sql, params)
  File "/home/liu/.virtualenvs/python2/local/lib/python2.7/site-packages/django/db/utils.py", line 95, in __exit__
    six.reraise(dj_exc_type, dj_exc_value, traceback)
  File "/home/liu/.virtualenvs/python2/local/lib/python2.7/site-packages/django/db/backends/utils.py", line 64, in execute
    return self.cursor.execute(sql, params)
  File "/home/liu/.virtualenvs/python2/local/lib/python2.7/site-packages/django/db/backends/mysql/base.py", line 112, in execute
    return self.cursor.execute(query, args)
  File "/home/liu/.virtualenvs/python2/local/lib/python2.7/site-packages/pymysql/cursors.py", line 170, in execute
    result = self._query(query)
  File "/home/liu/.virtualenvs/python2/local/lib/python2.7/site-packages/pymysql/cursors.py", line 328, in _query
    conn.query(q)
  File "/home/liu/.virtualenvs/python2/local/lib/python2.7/site-packages/pymysql/connections.py", line 517, in query
    self._affected_rows = self._read_query_result(unbuffered=unbuffered)
  File "/home/liu/.virtualenvs/python2/local/lib/python2.7/site-packages/pymysql/connections.py", line 732, in _read_query_result
    result.read()
  File "/home/liu/.virtualenvs/python2/local/lib/python2.7/site-packages/pymysql/connections.py", line 1075, in read
    first_packet = self.connection._read_packet()
  File "/home/liu/.virtualenvs/python2/local/lib/python2.7/site-packages/pymysql/connections.py", line 684, in _read_packet
    packet.check_error()
  File "/home/liu/.virtualenvs/python2/local/lib/python2.7/site-packages/pymysql/protocol.py", line 220, in check_error
    err.raise_mysql_exception(self._data)
  File "/home/liu/.virtualenvs/python2/local/lib/python2.7/site-packages/pymysql/err.py", line 109, in raise_mysql_exception
    raise errorclass(errno, errval)
ProgrammingError: (1146, u"Table 'usmpdb.nas_cluster' doesn't exist")
ERROR 2019-08-30 15:36:30,033 /home/liu/PycharmProjects/USMP/nas/views.py views.py views getNetappNasFailoverStatus 144: [Errno 2] No such file or directory: 'C:\\my_projects\\USMP\\USMP\\initdb\\nas_list.txt'
ERROR 2019-08-30 15:36:30,052 /home/liu/PycharmProjects/USMP/nas/views.py views.py views getNetappNasFsUsed 178: [Errno 2] No such file or directory: 'C:\\my_projects\\USMP\\USMP\\initdb\\nas_list.txt'
ERROR 2019-08-30 15:36:30,063 /home/liu/PycharmProjects/USMP/nas/views.py views.py views getNetappNasHealthStatus 210: [Errno 2] No such file or directory: 'C:\\my_projects\\USMP\\USMP\\initdb\\nas_list.txt'
ERROR 2019-08-30 15:36:30,073 /home/liu/PycharmProjects/USMP/nas/views.py views.py views getNetappNasEvent 247: [Errno 2] No such file or directory: 'C:\\my_projects\\USMP\\USMP\\initdb\\nas_list.txt'
ERROR 2019-08-30 15:54:15,258 /home/liu/PycharmProjects/USMP/nas/views.py views.py views getNetappNasFailoverStatus 144: [Errno 2] No such file or directory: 'C:\\my_projects\\USMP\\USMP\\initdb\\nas_list.txt'
ERROR 2019-08-30 15:54:15,268 /home/liu/PycharmProjects/USMP/nas/views.py views.py views getNetappNasFsUsed 178: [Errno 2] No such file or directory: 'C:\\my_projects\\USMP\\USMP\\initdb\\nas_list.txt'
ERROR 2019-08-30 15:54:15,276 /home/liu/PycharmProjects/USMP/nas/views.py views.py views getNetappNasHealthStatus 210: [Errno 2] No such file or directory: 'C:\\my_projects\\USMP\\USMP\\initdb\\nas_list.txt'
ERROR 2019-08-30 15:54:15,284 /home/liu/PycharmProjects/USMP/nas/views.py views.py views getNetappNasEvent 247: [Errno 2] No such file or directory: 'C:\\my_projects\\USMP\\USMP\\initdb\\nas_list.txt'
ERROR 2019-08-30 15:58:06,548 /home/liu/PycharmProjects/USMP/nas/views.py views.py views getNetappNasFailoverStatus 144: [Errno 2] No such file or directory: 'C:\\my_projects\\USMP\\USMP\\initdb\\nas_list.txt'
ERROR 2019-08-30 15:58:06,558 /home/liu/PycharmProjects/USMP/nas/views.py views.py views getNetappNasFsUsed 178: [Errno 2] No such file or directory: 'C:\\my_projects\\USMP\\USMP\\initdb\\nas_list.txt'
ERROR 2019-08-30 15:58:06,566 /home/liu/PycharmProjects/USMP/nas/views.py views.py views getNetappNasHealthStatus 210: [Errno 2] No such file or directory: 'C:\\my_projects\\USMP\\USMP\\initdb\\nas_list.txt'
ERROR 2019-08-30 15:58:06,576 /home/liu/PycharmProjects/USMP/nas/views.py views.py views getNetappNasEvent 247: [Errno 2] No such file or directory: 'C:\\my_projects\\USMP\\USMP\\initdb\\nas_list.txt'
ERROR 2019-08-30 16:01:19,101 /home/liu/PycharmProjects/USMP/nas/views.py views.py views getNetappNasFailoverStatus 144: [Errno 2] No such file or directory: 'C:\\my_projects\\USMP\\USMP\\initdb\\nas_list.txt'
ERROR 2019-08-30 16:01:19,114 /home/liu/PycharmProjects/USMP/nas/views.py views.py views getNetappNasFsUsed 178: [Errno 2] No such file or directory: 'C:\\my_projects\\USMP\\USMP\\initdb\\nas_list.txt'
ERROR 2019-08-30 16:01:19,126 /home/liu/PycharmProjects/USMP/nas/views.py views.py views getNetappNasHealthStatus 210: [Errno 2] No such file or directory: 'C:\\my_projects\\USMP\\USMP\\initdb\\nas_list.txt'
ERROR 2019-08-30 16:01:19,134 /home/liu/PycharmProjects/USMP/nas/views.py views.py views getNetappNasEvent 247: [Errno 2] No such file or directory: 'C:\\my_projects\\USMP\\USMP\\initdb\\nas_list.txt'
ERROR 2019-08-30 16:06:33,277 /home/liu/PycharmProjects/USMP/initdb/initNasDb.py initNasDb.py initNasDb sshConnect 44: [Errno 110] Connection timed out
ERROR 2019-08-30 16:06:33,277 /home/liu/PycharmProjects/USMP/initdb/initNasDb.py initNasDb.py initNasDb sshConnect 44: [Errno 110] Connection timed out
ERROR 2019-08-30 16:06:33,277 /home/liu/PycharmProjects/USMP/initdb/initNasDb.py initNasDb.py initNasDb sshConnect 44: [Errno 110] Connection timed out
INFO 2019-08-30 16:06:33,307 /home/liu/PycharmProjects/USMP/initdb/initNasDb.py initNasDb.py initNasDb initNasDb 246: run time : 130.024356 S
ERROR 2019-08-30 16:08:43,730 /home/liu/PycharmProjects/USMP/nas/views.py views.py views getNetappNasFailoverStatus 144: [Errno 2] No such file or directory: 'C:\\my_projects\\USMP\\USMP\\initdb\\nas_list.txt'
ERROR 2019-08-30 16:08:43,740 /home/liu/PycharmProjects/USMP/nas/views.py views.py views getNetappNasFsUsed 178: [Errno 2] No such file or directory: 'C:\\my_projects\\USMP\\USMP\\initdb\\nas_list.txt'
ERROR 2019-08-30 16:08:43,748 /home/liu/PycharmProjects/USMP/nas/views.py views.py views getNetappNasHealthStatus 210: [Errno 2] No such file or directory: 'C:\\my_projects\\USMP\\USMP\\initdb\\nas_list.txt'
ERROR 2019-08-30 16:08:43,756 /home/liu/PycharmProjects/USMP/nas/views.py views.py views getNetappNasEvent 247: [Errno 2] No such file or directory: 'C:\\my_projects\\USMP\\USMP\\initdb\\nas_list.txt'
ERROR 2019-08-30 16:08:44,349 /home/liu/PycharmProjects/USMP/initdb/initNasDb.py initNasDb.py initNasDb sshConnect 44: [Errno 110] Connection timed out
ERROR 2019-08-30 16:08:44,349 /home/liu/PycharmProjects/USMP/initdb/initNasDb.py initNasDb.py initNasDb sshConnect 44: [Errno 110] Connection timed out
ERROR 2019-08-30 16:08:44,349 /home/liu/PycharmProjects/USMP/initdb/initNasDb.py initNasDb.py initNasDb sshConnect 44: [Errno 110] Connection timed out
INFO 2019-08-30 16:08:44,420 /home/liu/PycharmProjects/USMP/initdb/initNasDb.py initNasDb.py initNasDb initNasDb 246: run time : 131.112230 S
ERROR 2019-08-30 16:08:49,591 /home/liu/PycharmProjects/USMP/nas/views.py views.py views getNetappNasFailoverStatus 144: [Errno 2] No such file or directory: 'C:\\my_projects\\USMP\\USMP\\initdb\\nas_list.txt'
ERROR 2019-08-30 16:08:49,601 /home/liu/PycharmProjects/USMP/nas/views.py views.py views getNetappNasFsUsed 178: [Errno 2] No such file or directory: 'C:\\my_projects\\USMP\\USMP\\initdb\\nas_list.txt'
ERROR 2019-08-30 16:08:49,609 /home/liu/PycharmProjects/USMP/nas/views.py views.py views getNetappNasHealthStatus 210: [Errno 2] No such file or directory: 'C:\\my_projects\\USMP\\USMP\\initdb\\nas_list.txt'
ERROR 2019-08-30 16:08:49,617 /home/liu/PycharmProjects/USMP/nas/views.py views.py views getNetappNasEvent 247: [Errno 2] No such file or directory: 'C:\\my_projects\\USMP\\USMP\\initdb\\nas_list.txt'
ERROR 2019-08-30 16:25:29,187 /home/liu/PycharmProjects/USMP/nas/views.py views.py views getNetappNasFailoverStatus 144: [Errno 2] No such file or directory: 'C:\\my_projects\\USMP\\USMP\\initdb\\nas_list.txt'
ERROR 2019-08-30 16:25:29,199 /home/liu/PycharmProjects/USMP/nas/views.py views.py views getNetappNasFsUsed 178: [Errno 2] No such file or directory: 'C:\\my_projects\\USMP\\USMP\\initdb\\nas_list.txt'
ERROR 2019-08-30 16:25:29,207 /home/liu/PycharmProjects/USMP/nas/views.py views.py views getNetappNasHealthStatus 210: [Errno 2] No such file or directory: 'C:\\my_projects\\USMP\\USMP\\initdb\\nas_list.txt'
ERROR 2019-08-30 16:25:29,220 /home/liu/PycharmProjects/USMP/nas/views.py views.py views getNetappNasEvent 247: [Errno 2] No such file or directory: 'C:\\my_projects\\USMP\\USMP\\initdb\\nas_list.txt'
ERROR 2019-08-30 17:07:19,336 /home/liu/PycharmProjects/USMP/nas/views.py views.py views getNetappNasFailoverStatus 144: [Errno 2] No such file or directory: 'C:\\my_projects\\USMP\\USMP\\initdb\\nas_list.txt'
ERROR 2019-08-30 17:07:19,349 /home/liu/PycharmProjects/USMP/nas/views.py views.py views getNetappNasFsUsed 178: [Errno 2] No such file or directory: 'C:\\my_projects\\USMP\\USMP\\initdb\\nas_list.txt'
ERROR 2019-08-30 17:07:19,358 /home/liu/PycharmProjects/USMP/nas/views.py views.py views getNetappNasHealthStatus 210: [Errno 2] No such file or directory: 'C:\\my_projects\\USMP\\USMP\\initdb\\nas_list.txt'
ERROR 2019-08-30 17:07:19,365 /home/liu/PycharmProjects/USMP/nas/views.py views.py views getNetappNasEvent 247: [Errno 2] No such file or directory: 'C:\\my_projects\\USMP\\USMP\\initdb\\nas_list.txt'
ERROR 2019-08-30 17:07:52,809 /home/liu/PycharmProjects/USMP/nas/views.py views.py views getNetappNasFailoverStatus 144: [Errno 2] No such file or directory: 'C:\\my_projects\\USMP\\USMP\\initdb\\nas_list.txt'
ERROR 2019-08-30 17:07:52,819 /home/liu/PycharmProjects/USMP/nas/views.py views.py views getNetappNasFsUsed 178: [Errno 2] No such file or directory: 'C:\\my_projects\\USMP\\USMP\\initdb\\nas_list.txt'
ERROR 2019-08-30 17:07:52,831 /home/liu/PycharmProjects/USMP/nas/views.py views.py views getNetappNasHealthStatus 210: [Errno 2] No such file or directory: 'C:\\my_projects\\USMP\\USMP\\initdb\\nas_list.txt'
ERROR 2019-08-30 17:07:52,840 /home/liu/PycharmProjects/USMP/nas/views.py views.py views getNetappNasEvent 247: [Errno 2] No such file or directory: 'C:\\my_projects\\USMP\\USMP\\initdb\\nas_list.txt'
