ERROR 2019-09-06 10:10:24,167 /home/liu/.virtualenvs/py2.7/local/lib/python2.7/site-packages/django/core/handlers/base.py base.py base handle_uncaught_exception 284: Internal Server Error: /getproducesan/
Traceback (most recent call last):
  File "/home/liu/.virtualenvs/py2.7/local/lib/python2.7/site-packages/django/core/handlers/base.py", line 149, in get_response
    response = self.process_exception_by_middleware(e, request)
  File "/home/liu/.virtualenvs/py2.7/local/lib/python2.7/site-packages/django/core/handlers/base.py", line 147, in get_response
    response = wrapped_callback(request, *callback_args, **callback_kwargs)
  File "/home/liu/.virtualenvs/py2.7/local/lib/python2.7/site-packages/django/views/decorators/csrf.py", line 58, in wrapped_view
    return view_func(*args, **kwargs)
  File "/home/liu/git_project/project-usmp/USMP/app01/views.py", line 63, in getproducesan
    producesan_list.append(model_to_dict(producesan.first()))
  File "/home/liu/.virtualenvs/py2.7/local/lib/python2.7/site-packages/django/forms/models.py", line 84, in model_to_dict
    opts = instance._meta
AttributeError: 'NoneType' object has no attribute '_meta'
